{"trial_id": "009", "hyperparameters": {"space": [{"class_name": "Int", "config": {"name": "num_neurons_main", "default": null, "conditions": [], "min_value": 20, "max_value": 100, "step": 20, "sampling": "linear"}}, {"class_name": "Int", "config": {"name": "num_layers_main", "default": null, "conditions": [], "min_value": 2, "max_value": 6, "step": 1, "sampling": "linear"}}, {"class_name": "Int", "config": {"name": "num_neurons_int", "default": null, "conditions": [], "min_value": 20, "max_value": 200, "step": 20, "sampling": "linear"}}, {"class_name": "Int", "config": {"name": "num_layers_int", "default": null, "conditions": [], "min_value": 2, "max_value": 10, "step": 2, "sampling": "linear"}}, {"class_name": "Int", "config": {"name": "num_keypoints", "default": null, "conditions": [], "min_value": 20, "max_value": 100, "step": 20, "sampling": "linear"}}, {"class_name": "Int", "config": {"name": "num_vertices", "default": null, "conditions": [], "min_value": 2, "max_value": 30, "step": 4, "sampling": "linear"}}, {"class_name": "Float", "config": {"name": "lambd_mc", "default": 1e-06, "conditions": [], "min_value": 1e-06, "max_value": 0.01, "step": null, "sampling": "log"}}, {"class_name": "Float", "config": {"name": "pi_mc", "default": 1e-06, "conditions": [], "min_value": 1e-06, "max_value": 0.01, "step": null, "sampling": "log"}}, {"class_name": "Float", "config": {"name": "smoothness_reg", "default": 1e-06, "conditions": [], "min_value": 1e-06, "max_value": 0.1, "step": null, "sampling": "log"}}], "values": {"num_neurons_main": 40, "num_layers_main": 5, "num_neurons_int": 160, "num_layers_int": 4, "num_keypoints": 20, "num_vertices": 10, "lambd_mc": 2.374497380261211e-06, "pi_mc": 1.1063557700635795e-06, "smoothness_reg": 0.09134262699235192}}, "metrics": {"metrics": {}}, "score": null, "best_step": 0, "status": "FAILED", "message": "Traceback (most recent call last):\n  File \"/Users/tupho/miniconda3/envs/keras2/lib/python3.11/site-packages/keras_tuner/src/engine/base_tuner.py\", line 274, in _try_run_and_update_trial\n    self._run_and_update_trial(trial, *fit_args, **fit_kwargs)\n  File \"/Users/tupho/miniconda3/envs/keras2/lib/python3.11/site-packages/keras_tuner/src/engine/base_tuner.py\", line 239, in _run_and_update_trial\n    results = self.run_trial(trial, *fit_args, **fit_kwargs)\n              ^^^^^^^^^^^^^^^^^^^^^^^^^^^^^^^^^^^^^^^^^^^^^^\n  File \"/Users/tupho/miniconda3/envs/keras2/lib/python3.11/site-packages/keras_tuner/src/engine/tuner.py\", line 314, in run_trial\n    obj_value = self._build_and_fit_model(trial, *args, **copied_kwargs)\n                ^^^^^^^^^^^^^^^^^^^^^^^^^^^^^^^^^^^^^^^^^^^^^^^^^^^^^^^^\n  File \"/Users/tupho/miniconda3/envs/keras2/lib/python3.11/site-packages/keras_tuner/src/engine/tuner.py\", line 233, in _build_and_fit_model\n    results = self.hypermodel.fit(hp, model, *args, **kwargs)\n              ^^^^^^^^^^^^^^^^^^^^^^^^^^^^^^^^^^^^^^^^^^^^^^^\n  File \"/Users/tupho/miniconda3/envs/keras2/lib/python3.11/site-packages/keras_tuner/src/engine/hypermodel.py\", line 149, in fit\n    return model.fit(*args, **kwargs)\n           ^^^^^^^^^^^^^^^^^^^^^^^^^^\n  File \"/Users/tupho/miniconda3/envs/keras2/lib/python3.11/site-packages/keras/src/utils/traceback_utils.py\", line 70, in error_handler\n    raise e.with_traceback(filtered_tb) from None\n  File \"/Users/tupho/miniconda3/envs/keras2/lib/python3.11/site-packages/tensorflow/python/eager/execute.py\", line 59, in quick_execute\n    except TypeError as e:\ntensorflow.python.framework.errors_impl.InvalidArgumentError: Graph execution error:\n\nDetected at node mul_24 defined at (most recent call last):\n  File \"<frozen runpy>\", line 198, in _run_module_as_main\n\n  File \"<frozen runpy>\", line 88, in _run_code\n\n  File \"/Users/tupho/miniconda3/envs/keras2/lib/python3.11/site-packages/ipykernel_launcher.py\", line 18, in <module>\n\n  File \"/Users/tupho/miniconda3/envs/keras2/lib/python3.11/site-packages/traitlets/config/application.py\", line 1075, in launch_instance\n\n  File \"/Users/tupho/miniconda3/envs/keras2/lib/python3.11/site-packages/ipykernel/kernelapp.py\", line 739, in start\n\n  File \"/Users/tupho/miniconda3/envs/keras2/lib/python3.11/site-packages/tornado/platform/asyncio.py\", line 205, in start\n\n  File \"/Users/tupho/miniconda3/envs/keras2/lib/python3.11/asyncio/base_events.py\", line 608, in run_forever\n\n  File \"/Users/tupho/miniconda3/envs/keras2/lib/python3.11/asyncio/base_events.py\", line 1936, in _run_once\n\n  File \"/Users/tupho/miniconda3/envs/keras2/lib/python3.11/asyncio/events.py\", line 84, in _run\n\n  File \"/Users/tupho/miniconda3/envs/keras2/lib/python3.11/site-packages/ipykernel/kernelbase.py\", line 545, in dispatch_queue\n\n  File \"/Users/tupho/miniconda3/envs/keras2/lib/python3.11/site-packages/ipykernel/kernelbase.py\", line 534, in process_one\n\n  File \"/Users/tupho/miniconda3/envs/keras2/lib/python3.11/site-packages/ipykernel/kernelbase.py\", line 437, in dispatch_shell\n\n  File \"/Users/tupho/miniconda3/envs/keras2/lib/python3.11/site-packages/ipykernel/ipkernel.py\", line 362, in execute_request\n\n  File \"/Users/tupho/miniconda3/envs/keras2/lib/python3.11/site-packages/ipykernel/kernelbase.py\", line 778, in execute_request\n\n  File \"/Users/tupho/miniconda3/envs/keras2/lib/python3.11/site-packages/ipykernel/ipkernel.py\", line 449, in do_execute\n\n  File \"/Users/tupho/miniconda3/envs/keras2/lib/python3.11/site-packages/ipykernel/zmqshell.py\", line 549, in run_cell\n\n  File \"/Users/tupho/miniconda3/envs/keras2/lib/python3.11/site-packages/IPython/core/interactiveshell.py\", line 3075, in run_cell\n\n  File \"/Users/tupho/miniconda3/envs/keras2/lib/python3.11/site-packages/IPython/core/interactiveshell.py\", line 3130, in _run_cell\n\n  File \"/Users/tupho/miniconda3/envs/keras2/lib/python3.11/site-packages/IPython/core/async_helpers.py\", line 128, in _pseudo_sync_runner\n\n  File \"/Users/tupho/miniconda3/envs/keras2/lib/python3.11/site-packages/IPython/core/interactiveshell.py\", line 3334, in run_cell_async\n\n  File \"/Users/tupho/miniconda3/envs/keras2/lib/python3.11/site-packages/IPython/core/interactiveshell.py\", line 3517, in run_ast_nodes\n\n  File \"/Users/tupho/miniconda3/envs/keras2/lib/python3.11/site-packages/IPython/core/interactiveshell.py\", line 3577, in run_code\n\n  File \"/var/folders/30/wpb2n_hs72q5fz9yvp8c1cth0000gv/T/ipykernel_55612/3720829584.py\", line 14, in <module>\n\n  File \"/Users/tupho/miniconda3/envs/keras2/lib/python3.11/site-packages/keras_tuner/src/engine/base_tuner.py\", line 234, in search\n\n  File \"/Users/tupho/miniconda3/envs/keras2/lib/python3.11/site-packages/keras_tuner/src/engine/base_tuner.py\", line 274, in _try_run_and_update_trial\n\n  File \"/Users/tupho/miniconda3/envs/keras2/lib/python3.11/site-packages/keras_tuner/src/engine/base_tuner.py\", line 239, in _run_and_update_trial\n\n  File \"/Users/tupho/miniconda3/envs/keras2/lib/python3.11/site-packages/keras_tuner/src/engine/tuner.py\", line 314, in run_trial\n\n  File \"/Users/tupho/miniconda3/envs/keras2/lib/python3.11/site-packages/keras_tuner/src/engine/tuner.py\", line 233, in _build_and_fit_model\n\n  File \"/Users/tupho/miniconda3/envs/keras2/lib/python3.11/site-packages/keras_tuner/src/engine/hypermodel.py\", line 149, in fit\n\n  File \"/Users/tupho/miniconda3/envs/keras2/lib/python3.11/site-packages/keras/src/utils/traceback_utils.py\", line 65, in error_handler\n\n  File \"/Users/tupho/miniconda3/envs/keras2/lib/python3.11/site-packages/keras/src/engine/training.py\", line 1856, in fit\n\n  File \"/Users/tupho/miniconda3/envs/keras2/lib/python3.11/site-packages/keras/src/utils/traceback_utils.py\", line 65, in error_handler\n\n  File \"/Users/tupho/miniconda3/envs/keras2/lib/python3.11/site-packages/keras/src/engine/training.py\", line 2296, in evaluate\n\n  File \"/Users/tupho/miniconda3/envs/keras2/lib/python3.11/site-packages/keras/src/engine/training.py\", line 4108, in run_step\n\n  File \"/Users/tupho/miniconda3/envs/keras2/lib/python3.11/site-packages/tensorflow/python/util/traceback_utils.py\", line 150, in error_handler\n\n  File \"/Users/tupho/miniconda3/envs/keras2/lib/python3.11/site-packages/tensorflow/python/eager/polymorphic_function/polymorphic_function.py\", line 832, in __call__\n\n  File \"/Users/tupho/miniconda3/envs/keras2/lib/python3.11/site-packages/tensorflow/python/eager/polymorphic_function/polymorphic_function.py\", line 888, in _call\n\n  File \"/Users/tupho/miniconda3/envs/keras2/lib/python3.11/site-packages/tensorflow/python/eager/polymorphic_function/polymorphic_function.py\", line 695, in _initialize\n\n  File \"/Users/tupho/miniconda3/envs/keras2/lib/python3.11/site-packages/tensorflow/python/eager/polymorphic_function/tracing_compilation.py\", line 178, in trace_function\n\n  File \"/Users/tupho/miniconda3/envs/keras2/lib/python3.11/site-packages/tensorflow/python/eager/polymorphic_function/tracing_compilation.py\", line 283, in _maybe_define_function\n\n  File \"/Users/tupho/miniconda3/envs/keras2/lib/python3.11/site-packages/tensorflow/python/eager/polymorphic_function/tracing_compilation.py\", line 310, in _create_concrete_function\n\n  File \"/Users/tupho/miniconda3/envs/keras2/lib/python3.11/site-packages/tensorflow/python/framework/func_graph.py\", line 1059, in func_graph_from_py_func\n\n  File \"/Users/tupho/miniconda3/envs/keras2/lib/python3.11/site-packages/tensorflow/python/eager/polymorphic_function/polymorphic_function.py\", line 598, in wrapped_fn\n\n  File \"/Users/tupho/miniconda3/envs/keras2/lib/python3.11/site-packages/tensorflow/python/eager/polymorphic_function/autograph_util.py\", line 41, in autograph_handler\n\n  File \"/Users/tupho/miniconda3/envs/keras2/lib/python3.11/site-packages/keras/src/engine/training.py\", line 2066, in test_function\n\n  File \"/Users/tupho/miniconda3/envs/keras2/lib/python3.11/site-packages/keras/src/engine/training.py\", line 2049, in step_function\n\n  File \"/Users/tupho/miniconda3/envs/keras2/lib/python3.11/site-packages/tensorflow/python/distribute/distribute_lib.py\", line 1681, in run\n\n  File \"/Users/tupho/miniconda3/envs/keras2/lib/python3.11/site-packages/tensorflow/python/distribute/distribute_lib.py\", line 3271, in call_for_each_replica\n\n  File \"/Users/tupho/miniconda3/envs/keras2/lib/python3.11/site-packages/tensorflow/python/distribute/distribute_lib.py\", line 4069, in _call_for_each_replica\n\n  File \"/Users/tupho/miniconda3/envs/keras2/lib/python3.11/site-packages/keras/src/engine/training.py\", line 2037, in run_step\n\n  File \"/Users/tupho/miniconda3/envs/keras2/lib/python3.11/site-packages/keras/src/engine/training.py\", line 1919, in test_step\n\n  File \"/Users/tupho/miniconda3/envs/keras2/lib/python3.11/site-packages/keras/src/engine/training.py\", line 1210, in compute_loss\n\n  File \"/Users/tupho/miniconda3/envs/keras2/lib/python3.11/site-packages/keras/src/engine/base_layer.py\", line 1428, in losses\n\n  File \"/Users/tupho/miniconda3/envs/keras2/lib/python3.11/site-packages/keras/src/engine/base_layer.py\", line 1509, in _tag_callable\n\n  File \"/var/folders/30/wpb2n_hs72q5fz9yvp8c1cth0000gv/T/ipykernel_55612/4125227462.py\", line 26, in smoothness_penalty\n\n  File \"/Users/tupho/miniconda3/envs/keras2/lib/python3.11/site-packages/tensorflow/python/util/traceback_utils.py\", line 150, in error_handler\n\n  File \"/Users/tupho/miniconda3/envs/keras2/lib/python3.11/site-packages/tensorflow/python/ops/math_ops.py\", line 1478, in binary_op_wrapper\n\n  File \"/Users/tupho/miniconda3/envs/keras2/lib/python3.11/site-packages/tensorflow/python/ops/math_ops.py\", line 1881, in _mul_dispatch\n\n  File \"/Users/tupho/miniconda3/envs/keras2/lib/python3.11/site-packages/tensorflow/python/ops/weak_tensor_ops.py\", line 142, in wrapper\n\n  File \"/Users/tupho/miniconda3/envs/keras2/lib/python3.11/site-packages/tensorflow/python/util/traceback_utils.py\", line 150, in error_handler\n\n  File \"/Users/tupho/miniconda3/envs/keras2/lib/python3.11/site-packages/tensorflow/python/util/dispatch.py\", line 1260, in op_dispatch_handler\n\n  File \"/Users/tupho/miniconda3/envs/keras2/lib/python3.11/site-packages/tensorflow/python/ops/math_ops.py\", line 530, in multiply\n\n  File \"/Users/tupho/miniconda3/envs/keras2/lib/python3.11/site-packages/tensorflow/python/ops/gen_math_ops.py\", line 6764, in mul\n\n  File \"/Users/tupho/miniconda3/envs/keras2/lib/python3.11/site-packages/tensorflow/python/framework/op_def_library.py\", line 796, in _apply_op_helper\n\n  File \"/Users/tupho/miniconda3/envs/keras2/lib/python3.11/site-packages/tensorflow/python/framework/func_graph.py\", line 670, in _create_op_internal\n\n  File \"/Users/tupho/miniconda3/envs/keras2/lib/python3.11/site-packages/tensorflow/python/framework/ops.py\", line 2652, in _create_op_internal\n\n  File \"/Users/tupho/miniconda3/envs/keras2/lib/python3.11/site-packages/tensorflow/python/framework/ops.py\", line 1160, in from_node_def\n\n  File \"/Users/tupho/miniconda3/envs/keras2/lib/python3.11/site-packages/tensorflow/python/util/traceback_utils.py\", line 150, in error_handler\n\n  File \"/Users/tupho/miniconda3/envs/keras2/lib/python3.11/site-packages/tensorflow/python/framework/ops.py\", line 1026, in _create_c_op\n\n  File \"/Users/tupho/miniconda3/envs/keras2/lib/python3.11/site-packages/tensorflow/python/util/tf_stack.py\", line 162, in extract_stack\n\nIncompatible shapes: [1000] vs. [0]\n\t [[{{node mul_24}}]] [Op:__inference_test_function_1282146]\n"}